# Manejo de errrores:
Tu enfoque para la gestión de errores parece sensato. Crear una clase `CustomError` que maneja la lógica de los errores de forma diferente según el entorno (desarrollo vs producción) es una buena práctica.

Sin embargo, hay algunas mejoras que podrías implementar en tu código actual:

1. En la definición de la clase, falta llamar al constructor de la clase padre (`super()`)
2. El método de instanciación que muestras al final tiene algunos problemas

Permíteme proponerte una versión mejorada:

Me parece una buena idea crear una clase para manejar los errores de forma distinta según el entorno. Sin embargo, encontré algunos problemas en tu implementación actual:

1. **Falta el `super()`**: Cuando extiendes de la clase Error, necesitas llamar al constructor de la clase padre.

2. **Problema con la asignación del método**: La forma en que estás asignando `throwError` como método independiente no mantendría la referencia al `this` dentro del método.

3. **Contexto del método**: Al separar el método de la instancia, perderías el contexto del `this.log`.

He preparado una versión mejorada que corrige estos problemas. El método `bind()` es clave aquí para mantener la referencia correcta al contexto de la instancia cuando exportas solamente el método `throwError`.

```javascript
class CustomError extends Error {
  constructor(log = false) {
    super();
    this.log = log;
  }

  throwError(message, status, err = null) {
    const error = new Error(message);
    error.status = Number(status) || 500;
    
    if (this.log && err) {
      console.error('Error:', err);
    }
    
    throw error;
  }
}

// Ejemplo de uso en diferentes entornos
const environment = process.env.NODE_ENV || 'development';

// Creamos una instancia según el entorno
const errorHandler = new CustomError(environment === 'development');

// Exportamos solo el método throwError
export const throwError = errorHandler.throwError.bind(errorHandler);

// En tus servicios simplemente usas:
// import { throwError } from './errorHandler';
// throwError('Mensaje de error', 400, originalError);
```

Este enfoque te permitirá:
- Tener un comportamiento diferente en desarrollo vs producción
- Una forma limpia de importar solo la función `throwError` en tus servicios
- Mantener la capacidad de mostrar información de depuración solo en entornos de desarrollo

¿Te parece útil esta implementación? ¿O prefieres otra aproximación para gestionar los errores?
<hr>

### Manejador de errores tambien en el catch

Sí, exacto. Colocarías tu función `throwError` en los bloques `catch` de tus servicios. Esto es una buena práctica para manejar errores de forma consistente. 

Aquí te muestro un ejemplo de cómo implementarías esto en un servicio típico:
```javascript
// userService.js
import { throwError } from '../utils/errorHandler';
import UserModel from '../models/UserModel';

export const userService = {
  async getAll() {
    try {
      const users = await UserModel.find({});
      return users;
    } catch (err) {
      // Aquí usas tu función throwError en el catch
      throwError('Error al obtener usuarios', 500, err);
    }
  },

  async getById(id) {
    try {
      const user = await UserModel.findById(id);
      
      if (!user) {
        // También puedes usar throwError para errores lógicos (no solo excepciones)
        throwError('Usuario no encontrado', 404);
      }
      
      return user;
    } catch (err) {
      // Si es un error de formato de ID de MongoDB
      if (err.name === 'CastError') {
        throwError('ID de usuario inválido', 400, err);
      }
      
      // Para otros errores inesperados
      throwError('Error al buscar usuario', 500, err);
    }
  },

  async create(userData) {
    try {
      // Validación básica
      if (!userData.email) {
        throwError('El email es requerido', 400);
      }
      
      // Verificar si ya existe
      const existingUser = await UserModel.findOne({ email: userData.email });
      if (existingUser) {
        throwError('Este email ya está registrado', 409);
      }
      
      const newUser = await UserModel.create(userData);
      return newUser;
    } catch (err) {
      // Manejo específico para errores de validación de MongoDB/Mongoose
      if (err.name === 'ValidationError') {
        throwError('Datos de usuario inválidos', 400, err);
      }
      
      // Para otros errores inesperados
      throwError('Error al crear usuario', 500, err);
    }
  }
};
```

Exactamente, utilizarías la función `throwError` en los bloques `catch` de tus servicios. Esta aproximación tiene varias ventajas:

1. **Manejo uniforme de errores**: Todos tus servicios manejarán los errores de la misma manera.

2. **Información de depuración condicional**: Solo se mostrará información detallada en desarrollo.

3. **Control de respuestas HTTP**: Puedes especificar fácilmente el código de estado apropiado para cada error.

4. **Centralización de la lógica de errores**: Si necesitas cambiar cómo manejas los errores, solo tendrás que modificar tu clase `CustomError`.

Como puedes ver en el ejemplo, puedes usar `throwError` en diferentes situaciones:

- Para manejar errores de la base de datos que ocurren en el `catch`
- Para errores lógicos como "usuario no encontrado"
- Para validaciones como campos requeridos
- Para manejar diferentes tipos de errores de forma específica (como errores de validación de MongoDB)

Esta estructura facilita mucho la gestión de errores y hace que tu código sea más limpio y mantenible. Además, te permite personalizar los mensajes de error y los códigos de estado HTTP según el contexto específico de cada error.

¿Hay algún caso específico de manejo de errores que te gustaría abordar?

<hr>

### Consulta:

 estaba comenzando a eliminar los try catch en mis services pero veo que con la nueva implementacion de throwError los necesito nuevamente, ya que si habia algun error proveniente de un ODM u ORM se arrojaba en bruto sin formatear, hay alguna opcion mejor en tu opinion que los try catch?

 Respuesta:

 Entiendo tu preocupación sobre tener que volver a usar try/catch en los servicios. Es una situación común cuando se busca un manejo de errores más sofisticado.

La pregunta es muy buena porque el manejo de errores siempre implica un balance entre:
1. Código limpio (menos try/catch)
2. Control detallado sobre los errores
3. Formato consistente de las respuestas de error

En mi opinión, hay algunas alternativas que podrías considerar:

### 1. Patrón de Wrapper para Servicios

```javascript
// serviceWrapper.js
import errorHandler from './errorHandler.js';

/**
 * Envuelve un servicio completo para manejar errores automáticamente
 * @param {Object} service - Objeto de servicio con múltiples métodos
 * @returns {Object} - Servicio con manejo de errores integrado
 */
export const wrapService = (service) => {
  const wrappedService = {};
  
  // Envuelve cada método del servicio con manejo de errores
  Object.keys(service).forEach(key => {
    if (typeof service[key] === 'function') {
      wrappedService[key] = async (...args) => {
        try {
          return await service[key](...args);
        } catch (err) {
          // Decide el código de estado basado en el tipo de error
          let status = 500;
          let message = 'Error interno del servidor';
          
          if (err.name === 'ValidationError') {
            status = 400;
            message = 'Error de validación';
          } else if (err.name === 'CastError') {
            status = 400;
            message = 'ID inválido';
          } else if (err.code === 11000) {
            status = 409;
            message = 'Registro duplicado';
          }
          
          errorHandler.throwError(message, status, err);
        }
      };
    } else {
      wrappedService[key] = service[key];
    }
  });
  
  return wrappedService;
};

// EJEMPLO DE USO:

// Definición del servicio original, sin try/catch
const userServiceRaw = {
  async getAll() {
    return await UserModel.find({});
  },
  
  async getById(id) {
    const user = await UserModel.findById(id);
    if (!user) {
      errorHandler.throwError('Usuario no encontrado', 404);
    }
    return user;
  }
};

// Exporta el servicio envuelto con manejo de errores
export const userService = wrapService(userServiceRaw);

```

### 2. Alto Orden para Métodos de Servicio

```javascript
// serviceError.js
import errorHandler from './errorHandler.js';

/**
 * Función de orden superior que envuelve métodos de servicio con manejo de errores
 * @param {Function} serviceMethod - Método del servicio a envolver
 * @returns {Function} - Método envuelto con manejo de errores
 */
export const withErrorHandling = (serviceMethod) => {
  return async (...args) => {
    try {
      return await serviceMethod(...args);
    } catch (err) {
      // Manejo común de errores
      if (err.name === 'ValidationError') {
        errorHandler.throwError('Datos inválidos', 400, err);
      } else if (err.name === 'CastError') {
        errorHandler.throwError('ID inválido', 400, err);
      } else if (err.code === 11000) {
        errorHandler.throwError('Registro duplicado', 409, err);
      }
      
      // Si el error ya tiene un status, probablemente fue lanzado con throwError
      if (err.status) {
        throw err;
      }
      
      // Error genérico
      errorHandler.throwError('Error en el servicio', 500, err);
    }
  };
};

// EJEMPLO DE USO:

// userService.js
import { withErrorHandling } from './serviceError.js';
import errorHandler from './errorHandler.js';

export const userService = {
  // Sin try/catch en el método
  getAll: withErrorHandling(async () => {
    return await UserModel.find({});
  }),
  
  // Sin try/catch pero con validación explícita
  getById: withErrorHandling(async (id) => {
    const user = await UserModel.findById(id);
    if (!user) {
      errorHandler.throwError('Usuario no encontrado', 404);
    }
    return user;
  })
};
```

### 3. Middleware Global para Express

```javascript
// errorMiddleware.js
import env from './envConfig.js';

export const globalErrorHandler = (err, req, res, next) => {
  // Status por defecto o el definido en el error
  const status = err.status || 500;
  
  // Mensaje por defecto o el del error
  const message = err.message || 'Error interno del servidor';
  
  // En desarrollo, devuelve detalles del error
  const errorResponse = {
    success: false,
    message,
    ...(env.Status === 'development' && { 
      stack: err.stack,
      details: err.details || err
    })
  };
  
  // Log solo en desarrollo
  if (env.Status === 'development') {
    console.error('Error:', err);
  }
  
  return res.status(status).json(errorResponse);
};

// En tu app.js
// app.use(globalErrorHandler);
```

### Mi opinión sobre la mejor aproximación

En mi experiencia, el enfoque más efectivo es una **combinación** de estas técnicas:

1. **Mantener el `catchController`** que ya tienes implementado - es excelente para simplificar el manejo de errores en los controladores.

2. **Implementar un middleware global de error** (opción 3) para capturar todos los errores no manejados y darles un formato consistente.

3. **Decidir caso por caso** sobre try/catch en los servicios:
   - Para operaciones simples: usar el patrón de alto orden (opción 2)
   - Para servicios complejos o donde necesitas manejos específicos: mantener try/catch

**Mi recomendación final:**

No veo los try/catch como algo necesariamente negativo, especialmente en los servicios donde la lógica de negocio puede requerir manejo específico de errores. Son explícitos y hacen el código más predecible.

Lo ideal sería:
- Usar try/catch en servicios con lógica compleja donde necesitas control fino
- Usar funciones de alto orden para operaciones CRUD simples
- Combinar todo con un buen middleware global de error

Esta combinación te dará el mejor balance entre código limpio y control detallado sobre los errores.

¿Esto se ajusta a la estructura y necesidades de tu aplicación?